<robot name="pupper_v3" version="1.0">

  <mujoco><compiler meshdir="../meshes/stl/" discardvisual="false" /></mujoco><joint name="leg_front_r_1" type="revolute">
    <limit lower="-1.22000" upper="2.51000" effort="3.00000" velocity="100.00000" />
    <origin rpy="1.57080 0.00000 0.00000" xyz="0.07500 -0.08350 0.00000" />
    <parent link="base_link" />
    <child link="leg_front_r_1" />
    <axis xyz="0.00000 0.00000 1.00000" />
  </joint>
  <joint name="leg_front_r_2" type="revolute">
    <limit lower="-0.42000" upper="3.14000" effort="3.00000" velocity="100.00000" />
    <origin rpy="1.49199 -1.57080 -1.49198" xyz="0.00000 0.00000 0.00000" />
    <parent link="leg_front_r_1" />
    <child link="leg_front_r_2" />
    <axis xyz="0.00000 0.00000 1.00000" />
  </joint>
  <joint name="leg_front_r_wheel_joint" type="continuous">
    <origin rpy="-0.00000 1.57080 0.00000" xyz="0.03750 -0.04940 0.06850" />
    <parent link="leg_front_r_2" />
    <child link="leg_front_r_wheel"/>
    <axis xyz="0.00000 0.00000 1.00000" />
  </joint>

  <joint name="leg_front_l_1" type="revolute">
    <limit lower="-2.51000" upper="1.22000" effort="3.00000" velocity="100.00000" />
    <origin rpy="-1.57080 0.00000 0.00000" xyz="0.07500 0.08350 0.00000" />
    <parent link="base_link" />
    <child link="leg_front_l_1" />
    <axis xyz="0.00000 0.00000 1.00000" />
  </joint>
  <joint name="leg_front_l_2" type="revolute">
    <limit lower="-3.14000" upper="0.42000" effort="3.00000" velocity="100.00000" />
    <origin rpy="1.57080 1.57080 -1.57080" xyz="0.00000 0.00000 0.00000" />
    <parent link="leg_front_l_1" />
    <child link="leg_front_l_2" />
    <axis xyz="0.00000 0.00000 1.00000" />
  </joint>


  <joint name="leg_back_r_1" type="revolute">
    <limit lower="-1.22000" upper="2.51000" effort="3.00000" velocity="100.00000" />
    <origin rpy="1.57080 0.00000 0.00000" xyz="-0.07500 -0.07250 0.00000" />
    <parent link="base_link" />
    <child link="leg_back_r_1" />
    <axis xyz="0.00000 0.00000 1.00000" />
  </joint>
  <joint name="leg_back_r_2" type="revolute">
    <limit lower="-0.42000" upper="3.14000" effort="3.00000" velocity="100.00000" />
    <origin rpy="1.49199 -1.57080 -1.49198" xyz="0.00000 0.00000 0.00000" />
    <parent link="leg_back_r_1" />
    <child link="leg_back_r_2" />
    <axis xyz="0.00000 0.00000 1.00000" />
  </joint>

  <joint name="leg_back_l_1" type="revolute">
    <limit lower="-2.51000" upper="1.22000" effort="3.00000" velocity="100.00000" />
    <origin rpy="-1.57080 0.00000 0.00000" xyz="-0.07500 0.07250 0.00000" />
    <parent link="base_link" />
    <child link="leg_back_l_1" />
    <axis xyz="0.00000 0.00000 1.00000" />
  </joint>
  <joint name="leg_back_l_2" type="revolute">
    <limit lower="-3.14000" upper="0.42000" effort="3.00000" velocity="100.00000" />
    <origin rpy="1.57080 1.57080 -1.57080" xyz="0.00000 0.00000 0.00000" />
    <parent link="leg_back_l_1" />
    <child link="leg_back_l_2" />
    <axis xyz="0.00000 0.00000 1.00000" />
  </joint>


  <link name="base_link">
    <collision name="body_collision">
      <origin rpy="-1.57080 -0.00000 1.57080" xyz="0.02146 -0.00000 0.03345" />
      <geometry>
        <box size="0.009014 0.012758 0.025943" />
      </geometry>
    </collision>
    <inertial>
      <inertia ixx="0.00240" ixy="0.000000" ixz="-0.0005" iyy="0.00850" iyz="0.00000" izz="0.00850" />
      <origin rpy="0.00000 0.00000 0.00000" xyz="0.02500 0.00000 0.01500" />
      <mass value="1.506" />
    </inertial>
    <visual name="body">
      <origin rpy="-1.57080 -0.00000 1.57080" xyz="0.00000 0.00000 0.00000" />
      <geometry>
        <mesh filename="package://pupper_v3_description/description/meshes/stl/BodyV4v70_001.stl" scale="1.00000 1.00000 1.00000" />
      </geometry>
    </visual>
  </link>
  <link name="leg_front_r_1">
    <inertial>
      <inertia ixx="0.000074" ixy="0.0" ixz="0.0" iyy="0.000058" iyz="0.0" izz="0.000048" />
      <origin rpy="0.00000 0.00000 0.00000" xyz="0.0 0.0 0.0" />
      <mass value="0.18000" />
    </inertial>
    <visual name="Leg Assembly For Flanged v26.001">
      <origin rpy="0.00000 0.00000 3.14159" xyz="0.00000 0.00000 -0.02800" />
      <geometry>
        <mesh filename="package://pupper_v3_description/description/meshes/stl/LegAssemblyForFlangedv26_001.stl" scale="1.00000 1.00000 1.00000" />
      </geometry>
    </visual>
  </link>
  <link name="leg_front_r_2">
    <inertial>
      <inertia ixx="0.000113" ixy="0.0" ixz="0.0" iyy="0.000067" iyz="0.000025" izz="0.000077" />
      <origin rpy="0.00000 0.00000 0.00000" xyz="0.0 -0.03340 0.05419" />
      <mass value="0.18600" />
    </inertial>
    <visual name="Leg Assembly For Flanged v26.002">
      <origin rpy="0.26213 -1.57080 2.87947" xyz="-0.02800 -0.00000 -0.00000" />
      <geometry>
        <mesh filename="package://pupper_v3_description/description/meshes/stl/LegAssemblyForFlangedv26_002.stl" scale="1.00000 1.00000 1.00000" />
      </geometry>
    </visual>
  </link>
  <link name="leg_front_r_wheel">
    <collision>
      <geometry>
        <cylinder radius="0.045" length="0.05"/>
      </geometry>
    </collision>
    <inertial>
      <mass value="0.1"/>
      <inertia ixx="0.0001" ixy="0" ixz="0" iyy="0.0001" iyz="0" izz="0.0001"/>
    </inertial>
    <visual>
      <geometry>
        <cylinder radius="0.045" length="0.05"/>
      </geometry>
    </visual>
  </link>
  <link name="leg_front_l_1">
    <inertial>
      <inertia ixx="0.000074" ixy="0.0" ixz="0.0" iyy="0.000058" iyz="0.0" izz="0.000048" />
      <origin rpy="0.00000 0.00000 0.00000" xyz="0.0 0.0 0.0" />
      <mass value="0.18000" />
    </inertial>
    <visual name="Leg Assembly For Flanged v26.009">
      <origin rpy="0.00000 0.00000 3.14159" xyz="0.00000 0.00000 -0.02800" />
      <geometry>
        <mesh filename="package://pupper_v3_description/description/meshes/stl/LegAssemblyForFlangedv26_010.stl" scale="1.00000 -1.00000 1.00000" />
      </geometry>
    </visual>
  </link>
  <link name="leg_front_l_2">
    <inertial>
      <inertia ixx="0.000113" ixy="0.0" ixz="0.0" iyy="0.000067" iyz="0.000025" izz="0.000077" />
      <origin rpy="0.00000 0.00000 0.00000" xyz="0 -0.03340 0.05419" />
      <mass value="0.18600" />
    </inertial>
    <visual name="Leg Assembly For Flanged v26.010">
      <origin rpy="0.26213 -1.57080 2.87947" xyz="+0.02800 -0.00000 -0.00000" />
      <geometry>
        <mesh filename="package://pupper_v3_description/description/meshes/stl/LegAssemblyForFlangedv26_011.stl" scale="1.00000 1.00000 -1.00000" />
      </geometry>
    </visual>
  </link>

  <link name="leg_back_r_1">
    <inertial>
      <inertia ixx="0.000074" ixy="0.0" ixz="0.0" iyy="0.000058" iyz="0.0" izz="0.000048" />
      <origin rpy="0.00000 0.00000 0.00000" xyz="0.0 0.0 0.0" />
      <mass value="0.18000" />
    </inertial>
    <visual name="Leg Assembly For Flanged v26.004">
      <origin rpy="0.00000 0.00000 3.14159" xyz="0.00000 0.00000 -0.02800" />
      <geometry>
        <mesh filename="package://pupper_v3_description/description/meshes/stl/LegAssemblyForFlangedv26_005.stl" scale="1.00000 1.00000 1.00000" />
      </geometry>
    </visual>
  </link>
  <link name="leg_back_r_2">
    <inertial>
      <inertia ixx="0.000113" ixy="0.0" ixz="0.0" iyy="0.000067" iyz="0.000025" izz="0.000077" />
      <origin rpy="0.00000 0.00000 0.00000" xyz="0.0 -0.03340 0.05419" />
      <mass value="0.18600" />
    </inertial>
    <visual name="Leg Assembly For Flanged v26.005">
      <origin rpy="0.26213 -1.57080 2.87947" xyz="-0.02800 -0.00000 -0.00000" />
      <geometry>
        <mesh filename="package://pupper_v3_description/description/meshes/stl/LegAssemblyForFlangedv26_006.stl" scale="1.00000 1.00000 1.00000" />
      </geometry>
    </visual>
  </link>

  <link name="leg_back_l_1">
    <inertial>
      <inertia ixx="0.000074" ixy="0.0" ixz="0.0" iyy="0.000058" iyz="0.0" izz="0.000048" />
      <origin rpy="0.00000 0.00000 0.00000" xyz="0.0 0.0 0.0" />
      <mass value="0.18000" />
    </inertial>
    <visual name="Leg Assembly For Flanged v26.012">
      <origin rpy="0.00000 0.00000 3.14159" xyz="0.00000 0.00000 -0.02800" />
      <geometry>
        <mesh filename="package://pupper_v3_description/description/meshes/stl/LegAssemblyForFlangedv26_013.stl" scale="1.00000 -1.00000 1.00000" />
      </geometry>
    </visual>
  </link>
  <link name="leg_back_l_2">
    <inertial>
      <inertia ixx="0.000113" ixy="0.0" ixz="0.0" iyy="0.000067" iyz="0.000025" izz="0.000077" />
      <origin rpy="0.00000 0.00000 0.00000" xyz="0.0 -0.03340 0.05419" />
      <mass value="0.18600" />
    </inertial>
    <visual name="Leg Assembly For Flanged v26.013">
      <origin rpy="0.26213 -1.57080 2.87947" xyz=" +0.02800 -0.00000 -0.00000" />
      <geometry>
        <mesh filename="package://pupper_v3_description/description/meshes/stl/LegAssemblyForFlangedv26_014.stl" scale="1.00000 1.00000 -1.00000" />
      </geometry>
    </visual>
  </link>
  

  <link name="leg_front_l_wheel">
    <visual>
      <geometry>
        <cylinder radius="0.045" length="0.05"/>
      </geometry>
    </visual>
    <collision>
      <geometry>
        <cylinder radius="0.045" length="0.05"/>
      </geometry>
    </collision>
    <inertial>
      <mass value="0.1"/>
      <inertia ixx="0.0001" ixy="0" ixz="0" iyy="0.0001" iyz="0" izz="0.0001"/>
    </inertial>
  </link>
  <joint name="leg_front_l_wheel_joint" type="continuous">
    <parent link="leg_front_l_2"/>
    <child link="leg_front_l_wheel"/>
    <origin rpy="-0.00000 1.57080 0.00000" xyz="-0.03750 -0.04940 0.06850"/>
    <axis xyz="0 0 1"/>
  </joint>

  <link name="leg_back_r_wheel">
    <visual>
      <geometry>
        <cylinder radius="0.045" length="0.05"/>
      </geometry>
    </visual>
    <collision>
      <geometry>
        <cylinder radius="0.045" length="0.05"/>
      </geometry>
    </collision>
    <inertial>
      <mass value="0.1"/>
      <inertia ixx="0.0001" ixy="0" ixz="0" iyy="0.0001" iyz="0" izz="0.0001"/>
    </inertial>
  </link>
  <joint name="leg_back_r_wheel_joint" type="continuous">
    <parent link="leg_back_r_2"/>
    <child link="leg_back_r_wheel"/>
    <origin rpy="-0.00000 1.57080 0.00000" xyz="0.03750 -0.04940 0.06850"/>
    <axis xyz="0 0 1"/>
  </joint>

  <link name="leg_back_l_wheel">
    <visual>
      <geometry>
        <cylinder radius="0.045" length="0.05"/>
      </geometry>
    </visual>
    <collision>
      <geometry>
        <cylinder radius="0.045" length="0.05"/>
      </geometry>
    </collision>
    <inertial>
      <mass value="0.1"/>
      <inertia ixx="0.0001" ixy="0" ixz="0" iyy="0.0001" iyz="0" izz="0.0001"/>
    </inertial>
  </link>
  <joint name="leg_back_l_wheel_joint" type="continuous">
    <parent link="leg_back_l_2"/>
    <child link="leg_back_l_wheel"/>
    <origin rpy="-0.00000 1.57080 0.00000" xyz="-0.03750 -0.04940 0.06850"/>
    <axis xyz="0 0 1"/>
  </joint>

<joint name="world_to_body" type="floating"><parent link="world" /><child link="base_link" /></joint><link name="world" /></robot>